<?xml version="1.0"?>
<robot name="scara_robot" xmlns:xacro="http://www.ros.org/wiki/xacro">

    <material name="grey"><color rgba="0.5 0.5 0.5 1.0"/></material>
    <material name="blue"><color rgba="0.0 0.0 0.8 1.0"/></material>
    <material name="red"><color rgba="0.8 0.0 0.0 1.0"/></material>

    <xacro:macro name="cylinder_inertia" params="m r h">
        <inertial>
            <mass value="${m}"/>
            <inertia ixx="${(m/12)*(3*r*r+h*h)}" ixy="0" ixz="0" iyy="${(m/12)*(3*r*r+h*h)}" iyz="0" izz="${(m/2)*(r*r)}"/>
        </inertial>
    </xacro:macro>
    <xacro:macro name="box_inertia" params="m x y z">
        <inertial>
            <mass value="${m}"/>
            <inertia ixx="${(m/12)*(y*y+z*z)}" ixy="0" ixz="0" iyy="${(m/12)*(x*x+z*z)}" iyz="0" izz="${(m/12)*(x*x+y*y)}"/>
        </inertial>
    </xacro:macro>

    <link name="base_footprint"/>

    <joint name="base_footprint_joint" type="fixed">
        <parent link="base_footprint"/>
        <child link="base_link"/>
        <origin xyz="0 0 0" rpy="0 0 0"/>
    </joint>

    <link name="base_link">
        <visual>
            <origin xyz="0 0 0.1" rpy="0 0 0"/>
            <geometry><cylinder radius="0.1" length="0.2"/></geometry>
            <material name="grey"/>
        </visual>
        <collision>
            <origin xyz="0 0 0.1" rpy="0 0 1.5708"/>
            <geometry><cylinder radius="0.1" length="0.2"/></geometry>
        </collision>
        <xacro:cylinder_inertia m="5.0" r="0.1" h="0.2"/>
    </link>

    <joint name="joint1" type="revolute">
        <parent link="base_link"/>
        <child link="link1"/>
        <origin xyz="0 0 0.2" rpy="0 0 0"/>
        <axis xyz="0 0 1"/>
        <limit lower="-2.5" upper="2.5" effort="100.0" velocity="1.0"/>
        <dynamics damping="0.1" friction="0.1"/>
    </joint>

    <link name="link1">
        <visual>
            <origin xyz="0.15 0 0.05" rpy="0 0 0"/>
            <geometry><box size="0.3 0.08 0.1"/></geometry>
            <material name="blue"/>
        </visual>
        <collision>
            <origin xyz="0.15 0 0.05" rpy="0 0 0"/>
            <geometry><box size="0.3 0.08 0.1"/></geometry>
        </collision>
        <xacro:box_inertia m="2.0" x="0.3" y="0.08" z="0.1"/>
    </link>

    <joint name="joint2" type="revolute">
        <parent link="link1"/>
        <child link="link2"/>
        <origin xyz="0.3 0 0.1" rpy="0 0 0"/>
        <axis xyz="0 0 1"/>
        <limit lower="-2.5" upper="2.5" effort="100.0" velocity="1.0"/>
        <dynamics damping="0.1" friction="0.1"/>
    </joint>

    <link name="link2">
        <visual>
            <origin xyz="0.1 0 0.05" rpy="0 0 0"/>
            <geometry><box size="0.2 0.06 0.1"/></geometry>
            <material name="red"/>
        </visual>
        <collision>
            <origin xyz="0.1 0 0.05" rpy="0 0 0"/>
            <geometry><box size="0.2 0.06 0.1"/></geometry>
        </collision>
        <xacro:box_inertia m="1.5" x="0.2" y="0.06" z="0.1"/>
    </link>

    <joint name="joint3" type="prismatic">
        <parent link="link2"/>
        <child link="end_effector"/>
        <origin xyz="0.2 0 0" rpy="0 0 0"/>
        <axis xyz="0 0 1"/>
        <limit lower="-0.15" upper="0.05" effort="50.0" velocity="0.5"/>
        <dynamics damping="0.1" friction="0.1"/>
    </joint>

    <link name="end_effector">
        <visual>
            <origin xyz="0 0 0" rpy="0 0 0"/>
            <geometry><cylinder radius="0.02" length="0.3"/></geometry>
            <material name="grey"/>
        </visual>
        <collision>
            <origin xyz="0 0 0" rpy="0 0 0"/>
            <geometry><cylinder radius="0.02" length="0.3"/></geometry>
        </collision>
        <xacro:cylinder_inertia m="0.5" r="0.02" h="0.3"/>
    </link>

    <joint name="joint4" type="fixed">
        <origin xyz="0.0 0.0 -0.1" rpy="0 0 0"/>
        <parent link="end_effector"/>
        <child link="red_cube"/>
    </joint>

    <link name="red_cube">
        <visual>
            <origin xyz="0.0 0.0 -0.1" rpy="0 0 0"/>
            <geometry>
                <box size="0.01 0.01 0.01" />
            </geometry>
            <material name="red"/>
        </visual>
        <xacro:box_inertia m="0.01" x="0.01" y="0.08" z="0.01"/>
    </link>

    <!-- STEP 12 - Table camera -->
    <joint type="fixed" name="table_camera_joint">
        <origin xyz="0.25 0.0 1.5" rpy="0 0 0"/>
        <child link="table_camera_link"/>
        <parent link="base_link"/>
    </joint>

    <link name='table_camera_link'>
        <pose>0 0 0 0 0 0</pose>
        <inertial>
            <mass value="1.0e-03"/>
            <origin xyz="0 0 0" rpy="0 0 0"/>
            <inertia
                ixx="1e-6" ixy="0" ixz="0"
                iyy="1e-6" iyz="0"
                izz="1e-6"
            />
        </inertial>

        <visual>
            <origin xyz="0 0 0" rpy="0 0 0"/>
            <geometry>
                <box size=".05 .05 .05"/>
            </geometry>
            <material name="red"/>
        </visual>
    </link>

    <joint type="fixed" name="table_camera_optical_joint">
        <origin xyz="0 0 0" rpy="-1.5707 0 -1.5707"/>
        <child link="table_camera_link_optical"/>
        <parent link="table_camera_link"/>
    </joint>

    <link name="table_camera_link_optical">
    </link>

    <ros2_control name="GazeboSystem" type="system">
        <hardware>
            <plugin>gz_ros2_control/GazeboSimSystem</plugin>
        </hardware>
        <joint name="joint1">
            <command_interface name="position">
                <param name="min">-2.5</param>
                <param name="max">2.5</param>
            </command_interface>
            <state_interface name="position">
                <param name="initial_value">0.0</param>
            </state_interface>
            <state_interface name="velocity"/>
            <state_interface name="effort"/>
        </joint>
        <joint name="joint2">
            <command_interface name="position">
                <param name="min">-2.5</param>
                <param name="max">2.5</param>
            </command_interface>
            <state_interface name="position">
                <param name="initial_value">0.0</param>
            </state_interface>
            <state_interface name="velocity"/>
            <state_interface name="effort"/>
        </joint>
        <joint name="joint3">
            <command_interface name="position">
                <param name="min">-0.15</param>
                <param name="max">0.05</param>
            </command_interface>
            <state_interface name="position">
                <param name="initial_value">0.0</param>
            </state_interface>
            <state_interface name="velocity"/>
            <state_interface name="effort"/>
        </joint>
    </ros2_control>

    <gazebo>
        <plugin filename="/opt/ros/jazzy/lib/libgz_ros2_control-system.so" name="gz_ros2_control::GazeboSimROS2ControlPlugin">
            <parameters>$(find projekt)/config/controller_position.yaml</parameters>
        </plugin>
    </gazebo>

    <gazebo>
        <plugin filename="gz-sim-detachable-joint-system" name="gz::sim::systems::DetachableJoint">
            <parent_link>end_effector</parent_link>
            <child_model>wood_cube_5cm</child_model>
            <child_link>link</child_link>
            <detach_topic>/wood_cube_5cm/detach</detach_topic>
            <attach_topic>/wood_cube_5cm/attach</attach_topic>
            <output_topic>/wood_cube_5cm/state</output_topic>
        </plugin>
    </gazebo>
    
    <gazebo reference="end_effector">
        <sensor name='sensor_contact' type='contact'>
            <contact>
                <collision>end_effector_collision</collision>
                <topic>/contact_end_effector</topic>
            </contact>
            <always_on>1</always_on>
            <update_rate>100</update_rate>
        </sensor>
    </gazebo>

    <gazebo reference="table_camera_link">
        <sensor name="camera" type="camera">
            <camera>
                <horizontal_fov>1.3962634</horizontal_fov>
                <image>
                <width>640</width>
                <height>480</height>
                <format>R8G8B8</format>
                </image>
                <clip>
                <near>0.1</near>
                <far>15</far>
                </clip>
                <noise>
                <type>gaussian</type>
                <!-- Noise is sampled independently per pixel on each frame.
                    That pixel's noise value is added to each of its color
                    channels, which at that point lie in the range [0,1]. -->
                <mean>0.0</mean>
                <stddev>0.007</stddev>
                </noise>
                <optical_frame_id>table_camera_link_optical</optical_frame_id>
                <camera_info_topic>table_camera/camera_info</camera_info_topic>
            </camera>
            <always_on>1</always_on>
            <update_rate>20</update_rate>
            <visualize>true</visualize>
            <topic>table_camera/image</topic>
        </sensor>
    </gazebo>

</robot>
