<?xml version="1.0"?>
<robot name="scara_robot" xmlns:xacro="http://www.ros.org/wiki/xacro">

    <material name="grey"><color rgba="0.5 0.5 0.5 1.0"/></material>
    <material name="blue"><color rgba="0.0 0.0 0.8 1.0"/></material>
    <material name="red"><color rgba="0.8 0.0 0.0 1.0"/></material>

    <xacro:macro name="cylinder_inertia" params="m r h">
        <inertial>
            <mass value="${m}"/>
            <inertia ixx="${(m/12)*(3*r*r+h*h)}" ixy="0" ixz="0" iyy="${(m/12)*(3*r*r+h*h)}" iyz="0" izz="${(m/2)*(r*r)}"/>
        </inertial>
    </xacro:macro>
    <xacro:macro name="box_inertia" params="m x y z">
        <inertial>
            <mass value="${m}"/>
            <inertia ixx="${(m/12)*(y*y+z*z)}" ixy="0" ixz="0" iyy="${(m/12)*(x*x+z*z)}" iyz="0" izz="${(m/12)*(x*x+y*y)}"/>
        </inertial>
    </xacro:macro>

    <link name="world" />
    <joint name="world_joint" type="fixed">
        <parent link="world"/>
        <child link="base_link"/>
        <origin xyz="0 0 0" rpy="0 0 0"/>
    </joint>

    <link name="base_link">
        <visual>
            <origin xyz="0 0 0.1" rpy="0 0 0"/>
            <geometry><cylinder radius="0.1" length="0.2"/></geometry>
            <material name="grey"/>
        </visual>
        <collision>
            <origin xyz="0 0 0.1" rpy="0 0 0"/>
            <geometry><cylinder radius="0.1" length="0.2"/></geometry>
        </collision>
        <xacro:cylinder_inertia m="5.0" r="0.1" h="0.2"/>
    </link>

    <joint name="joint1" type="revolute">
        <parent link="base_link"/>
        <child link="link1"/>
        <origin xyz="0 0 0.2" rpy="0 0 0"/>
        <axis xyz="0 0 1"/>
        <limit lower="-2.5" upper="2.5" effort="100.0" velocity="1.0"/>
        <dynamics damping="0.1" friction="0.1"/>
    </joint>

    <link name="link1">
        <visual>
            <origin xyz="0.15 0 0.05" rpy="0 0 0"/>
            <geometry><box size="0.3 0.08 0.1"/></geometry>
            <material name="blue"/>
        </visual>
        <collision>
            <origin xyz="0.15 0 0.05" rpy="0 0 0"/>
            <geometry><box size="0.3 0.08 0.1"/></geometry>
        </collision>
        <xacro:box_inertia m="2.0" x="0.3" y="0.08" z="0.1"/>
    </link>

    <joint name="joint2" type="revolute">
        <parent link="link1"/>
        <child link="link2"/>
        <origin xyz="0.3 0 0.1" rpy="0 0 0"/>
        <axis xyz="0 0 1"/>
        <limit lower="-2.5" upper="2.5" effort="100.0" velocity="1.0"/>
        <dynamics damping="0.1" friction="0.1"/>
    </joint>

    <link name="link2">
        <visual>
            <origin xyz="0.1 0 0.05" rpy="0 0 0"/>
            <geometry><box size="0.2 0.06 0.1"/></geometry>
            <material name="red"/>
        </visual>
        <collision>
            <origin xyz="0.1 0 0.05" rpy="0 0 0"/>
            <geometry><box size="0.2 0.06 0.1"/></geometry>
        </collision>
        <xacro:box_inertia m="1.5" x="0.2" y="0.06" z="0.1"/>
    </link>

    <joint name="joint3" type="prismatic">
        <parent link="link2"/>
        <child link="end_effector"/>
        <origin xyz="0.2 0 0" rpy="0 0 0"/>
        <axis xyz="0 0 1"/>
        <limit lower="-0.15" upper="0.05" effort="50.0" velocity="0.5"/>
        <dynamics damping="0.1" friction="0.1"/>
    </joint>

    <link name="end_effector">
        <visual>
            <origin xyz="0 0 0" rpy="0 0 0"/>
            <geometry><cylinder radius="0.02" length="0.3"/></geometry>
            <material name="grey"/>
        </visual>
        <collision>
            <origin xyz="0 0 0" rpy="0 0 0"/>
            <geometry><cylinder radius="0.02" length="0.3"/></geometry>
        </collision>
        <xacro:cylinder_inertia m="0.5" r="0.02" h="0.3"/>
    </link>

</robot>